Workbook
Name CARTERA_2025: Tabla134[#All]
Name CARTERA_2025: CARTERA_2026[#All]
Name CARTERA_2025: Tabla13[#All]

Sheet CARTERA 2024
A1: RUT | B1: RAZON | C1: VENDEDOR | E1: =MID(A1, 1, 2) & "." & MID(A1, 3, 3) & "." & MID(A1, 6, 3) & "-" & RIGHT(A1, 1) -> RU.T.-T | F1: SN | I1: Nota: Se actualizo la cartera 2025, sin embargo, cartera de SANTIAGO III Y SUR III pasan a atencion telefonica ya que no tienen vendedor.
A2: 611020171 | B2: HOSPITAL NAVAL ALMIRANTE NEF | C2: C VALENZUELA | E2: =VALUE(MID(Tabla1[[#This Row],[RUT]],1,LEN(Tabla1[[#This Row],[RUT]])-1)) -> 61102017 | F2: ="CN"&E2 -> CN61102017
A3: 616020366 | B3: HOSPITAL SAN JUAN DE DIOS DE LOS ANDES | C3: C VALENZUELA | E3: =VALUE(MID(Tabla1[[#This Row],[RUT]],1,LEN(Tabla1[[#This Row],[RUT]])-1)) -> 61602036 | F3: ="CN"&E3 -> CN61602036
A4: 616020382 | B4: HOSPITAL SAN CAMILO DE SAN FELIPE | C4: C VALENZUELA | E4: =VALUE(MID(Tabla1[[#This Row],[RUT]],1,LEN(Tabla1[[#This Row],[RUT]])-1)) -> 61602038 | F4: ="CN"&E4 -> CN61602038
A5: 616020544 | B5: HOSPITAL CARLOS VAN BUREN | C5: C VALENZUELA | E5: =VALUE(MID(Tabla1[[#This Row],[RUT]],1,LEN(Tabla1[[#This Row],[RUT]])-1)) -> 61602054 | F5: ="CN"&E5 -> CN61602054
A6: 616020579 | B6: HOSPITAL EDUARDO PEREIRA | C6: C VALENZUELA | E6: =VALUE(MID(Tabla1[[#This Row],[RUT]],1,LEN(Tabla1[[#This Row],[RUT]])-1)) -> 61602057 | F6: ="CN"&E6 -> CN61602057
A7: 616021265 | B7: HOSPITAL CLAUDIO VICUÑA | C7: C VALENZUELA | E7: =VALUE(MID(Tabla1[[#This Row],[RUT]],1,LEN(Tabla1[[#This Row],[RUT]])-1)) -> 61602126 | F7: ="CN"&E7 -> CN61602126
A8: 616064029 | B8: HOSPITAL LA SERENA | C8: C VALENZUELA | E8: =VALUE(MID(Tabla1[[#This Row],[RUT]],1,LEN(Tabla1[[#This Row],[RUT]])-1)) -> 61606402 | F8: ="CN"&E8 -> CN61606402
A9: 616064037 | B9: HOSPITAL COQUIMBO | C9: C VALENZUELA | E9: =VALUE(MID(Tabla1[[#This Row],[RUT]],1,LEN(Tabla1[[#This Row],[RUT]])-1)) -> 61606403 | F9: ="CN"&E9 -> CN61606403
A10: 616064045 | B10: HOSPITAL OVALLE | C10: C VALENZUELA | E10: =VALUE(MID(Tabla1[[#This Row],[RUT]],1,LEN(Tabla1[[#This Row],[RUT]])-1)) -> 61606404 | F10: ="CN"&E10 -> CN61606404
A11: 616065009 | B11: SERVICIO DE SALUD VALPARAISO SAN ANTONIO | C11: C VALENZUELA | E11: =VALUE(MID(Tabla1[[#This Row],[RUT]],1,LEN(Tabla1[[#This Row],[RUT]])-1)) -> 61606500 | F11: ="CN"&E11 -> CN61606500
A12: 616066021 | B12: HOSPITAL DR. GUSTAVO FRICKE | C12: C VALENZUELA | E12: =VALUE(MID(Tabla1[[#This Row],[RUT]],1,LEN(Tabla1[[#This Row],[RUT]])-1)) -> 61606602 | F12: ="CN"&E12 -> CN61606602
A13: 616066048 | B13: HOSPITAL DE QUILPUE | C13: C VALENZUELA | E13: =VALUE(MID(Tabla1[[#This Row],[RUT]],1,LEN(Tabla1[[#This Row],[RUT]])-1)) -> 61606604 | F13: ="CN"&E13 -> CN61606604
... A42: 995736004 | B42: CLINICA RIO BLANCO S.A | C42: C VALENZUELA | E42: =VALUE(MID(Tabla1[[#This Row],[RUT]],1,LEN(Tabla1[[#This Row],[RUT]])-1)) -> 99573600 | F42: ="CN"&E42 -> CN99573600
A43: 61606603K | B43: HOSPITAL ADRIANA COUSIÑO DE QUINTERO | C43: A TELEFONICA | E43: =VALUE(MID(Tabla1[[#This Row],[RUT]],1,LEN(Tabla1[[#This Row],[RUT]])-1)) -> 61606603 | F43: ="CN"&E43 -> CN61606603
A44: 137714132 | B44: EVELYN ARANDA ARANDA | C44: A TELEFONICA | E44: =VALUE(MID(Tabla1[[#This Row],[RUT]],1,LEN(Tabla1[[#This Row],[RUT]])-1)) -> 13771413 | F44: ="CN"&E44 -> CN13771413
A45: 159017230 | B45: MIGUEL EDUARDO PEÑA PARRA | C45: A TELEFONICA | E45: =VALUE(MID(Tabla1[[#This Row],[RUT]],1,LEN(Tabla1[[#This Row],[RUT]])-1)) -> 15901723 | F45: ="CN"&E45 -> CN15901723
A46: 164793079 | B46: DANIEL ALEJANDRO PINO MARTINEZ | C46: A TELEFONICA | E46: =VALUE(MID(Tabla1[[#This Row],[RUT]],1,LEN(Tabla1[[#This Row],[RUT]])-1)) -> 16479307 | F46: ="CN"&E46 -> CN16479307
A47: 609110007 | B47: UNIVERSIDAD DE SANTIAGO DE CHILE | C47: A TELEFONICA | E47: =VALUE(MID(Tabla1[[#This Row],[RUT]],1,LEN(Tabla1[[#This Row],[RUT]])-1)) -> 60911000 | F47: ="CN"&E47 -> CN60911000
A48: 609210001 | B48: UNIVERSIDAD DE VALPARAISO | C48: A TELEFONICA | E48: =VALUE(MID(Tabla1[[#This Row],[RUT]],1,LEN(Tabla1[[#This Row],[RUT]])-1)) -> 60921000 | F48: ="CN"&E48 -> CN60921000
A49: 610040241 | B49: DIRECCION REGIONAL DE GENDARMERIA - VALPARAISO | C49: A TELEFONICA | E49: =VALUE(MID(Tabla1[[#This Row],[RUT]],1,LEN(Tabla1[[#This Row],[RUT]])-1)) -> 61004024 | F49: ="CN"&E49 -> CN61004024
A50: 611010311 | B50: CENTRAL ODONTOLÓGICA DEL EJÉRCITO - COE | C50: A TELEFONICA | E50: =VALUE(MID(Tabla1[[#This Row],[RUT]],1,LEN(Tabla1[[#This Row],[RUT]])-1)) -> 61101031 | F50: ="CN"&E50 -> CN61101031
A51: 611010826 | B51: CENTRO CLÍNICO MILITAR ARICA | C51: A TELEFONICA | E51: =VALUE(MID(Tabla1[[#This Row],[RUT]],1,LEN(Tabla1[[#This Row],[RUT]])-1)) -> 61101082 | F51: ="CN"&E51 -> CN61101082
A52: 611010869 | B52: HOSPITAL MILITAR DEL NORTE | C52: A TELEFONICA | E52: =VALUE(MID(Tabla1[[#This Row],[RUT]],1,LEN(Tabla1[[#This Row],[RUT]])-1)) -> 61101086 | F52: ="CN"&E52 -> CN61101086
A53: 611020295 | B53: HOSPITAL NAVAL CIRUJANO GUZMAN DE MAGALLANES | C53: A TELEFONICA | E53: =VALUE(MID(Tabla1[[#This Row],[RUT]],1,LEN(Tabla1[[#This Row],[RUT]])-1)) -> 61102029 | F53: ="CN"&E53 -> CN61102029
A54: 611020678 | B54: CENTRAL ODONTOLOGICA IIA ZONA NAVAL | C54: A TELEFONICA | E54: =VALUE(MID(Tabla1[[#This Row],[RUT]],1,LEN(Tabla1[[#This Row],[RUT]])-1)) -> 61102067 | F54: ="CN"&E54 -> CN61102067
A55: 611030193 | B55: ALA BASE N.1 | C55: A TELEFONICA | E55: =VALUE(MID(Tabla1[[#This Row],[RUT]],1,LEN(Tabla1[[#This Row],[RUT]])-1)) -> 61103019 | F55: ="CN"&E55 -> CN61103019
... A618: 995931702 | B618: CEGAMED CHILE S.A. | C618: A TELEFONICA | E618: =VALUE(MID(Tabla1[[#This Row],[RUT]],1,LEN(Tabla1[[#This Row],[RUT]])-1)) -> 99593170 | F618: ="CN"&E618 -> CN99593170
A619: 61004042K | B619: GENDARMERIA DE CHILE VI DIRECCION REGIONAL RANCAGUA | C619: A TELEFONICA | E619: =VALUE(MID(Tabla1[[#This Row],[RUT]],1,LEN(Tabla1[[#This Row],[RUT]])-1)) -> 61004042 | F619: ="CN"&E619 -> CN61004042
A620: 61108000K | B620: CAJA DE PREVISION DE LA DEFENSA NACIONAL | C620: A TELEFONICA | E620: =VALUE(MID(Tabla1[[#This Row],[RUT]],1,LEN(Tabla1[[#This Row],[RUT]])-1)) -> 61108000 | F620: ="CN"&E620 -> CN61108000
A621: 61601000K | B621: SUBSECRETARIA DE SALUD PUBLICA | C621: A TELEFONICA | E621: =VALUE(MID(Tabla1[[#This Row],[RUT]],1,LEN(Tabla1[[#This Row],[RUT]])-1)) -> 61601000 | F621: ="CN"&E621 -> CN61601000
A622: 61602132K | B622: HOSPITAL SANTA FILOMENA DE GRANEROS | C622: A TELEFONICA | E622: =VALUE(MID(Tabla1[[#This Row],[RUT]],1,LEN(Tabla1[[#This Row],[RUT]])-1)) -> 61602132 | F622: ="CN"&E622 -> CN61602132
A623: 61602146K | B623: HOSPITAL DE CHIMBARONGO | C623: A TELEFONICA | E623: =VALUE(MID(Tabla1[[#This Row],[RUT]],1,LEN(Tabla1[[#This Row],[RUT]])-1)) -> 61602146 | F623: ="CN"&E623 -> CN61602146
A624: 61602194K | B624: HOSPITAL DE COELEMU | C624: A TELEFONICA | E624: =VALUE(MID(Tabla1[[#This Row],[RUT]],1,LEN(Tabla1[[#This Row],[RUT]])-1)) -> 61602194 | F624: ="CN"&E624 -> CN61602194
A625: 61602244K | B625: HOSPITAL DE CUNCO | C625: A TELEFONICA | E625: =VALUE(MID(Tabla1[[#This Row],[RUT]],1,LEN(Tabla1[[#This Row],[RUT]])-1)) -> 61602244 | F625: ="CN"&E625 -> CN61602244
A626: 61602261K | B626: HOSPITAL DE PUERTO OCTAY | C626: A TELEFONICA | E626: =VALUE(MID(Tabla1[[#This Row],[RUT]],1,LEN(Tabla1[[#This Row],[RUT]])-1)) -> 61602261 | F626: ="CN"&E626 -> CN61602261
A627: 61602275K | B627: HOSPITAL DE CASTRO DR. AUGUSTO RIFFART | C627: M RUIZ | E627: =VALUE(MID(Tabla1[[#This Row],[RUT]],1,LEN(Tabla1[[#This Row],[RUT]])-1)) -> 61602275 | F627: ="CN"&E627 -> CN61602275
A628: 61602292K | B628: HOSPITAL COCHRANE | C628: A TELEFONICA | E628: =VALUE(MID(Tabla1[[#This Row],[RUT]],1,LEN(Tabla1[[#This Row],[RUT]])-1)) -> 61602292 | F628: ="CN"&E628 -> CN61602292
A629: 61602311K | B629: HOSPITAL CHAITEN | C629: A TELEFONICA | E629: =VALUE(MID(Tabla1[[#This Row],[RUT]],1,LEN(Tabla1[[#This Row],[RUT]])-1)) -> 61602311 | F629: ="CN"&E629 -> CN61602311
A630: 61606200K | B630: DIRECCIÓN SERVICIO DE SALUD ANTOFAGASTA | C630: A TELEFONICA | E630: =VALUE(MID(Tabla1[[#This Row],[RUT]],1,LEN(Tabla1[[#This Row],[RUT]])-1)) -> 61606200 | F630: ="CN"&E630 -> CN61606200
...

Sheet visitas ricardo
A1: VENDEDOR | B1: RICARDO ENRIQUE ARAYA GONZÁLEZ
A3: Etiquetas de fila | C3: 45756 | D3: 45757 | E3: 45758 | F3: 45761 | G3: 45762 | H3: 45763 | I3: 45764 | J3: 45768 | K3: 45769 | L3: 45770 | M3: 45771 | N3: 45772 | O3: 45775 | P3: 45776 | Q3: 45777
A4: CENTRO DE SALUD DR. VICTOR RIOS M. FERNANDEZ | R4: =SUM(C4:Q4) -> 0
A5: CLINICA ANDES SALUD CHILLAN S.A | N5: 1 | O5: 1 | Q5: 1 | R5: =SUM(C5:Q5) -> 3
A6: CLINICA ANDES SALUD CONCEPCION S.A | R6: =SUM(C6:Q6) -> 0
A7: CLINICA BIO BIO SPA | K7: 1 | R7: =SUM(C7:Q7) -> 1
A8: CLINICA LAS AMAPOLAS LIMITADA | F8: 1 | L8: 1 | O8: 1 | Q8: 1 | R8: =SUM(C8:Q8) -> 4
A9: CLINICA LOS ANDES DE LOS ANGELES | E9: 1 | K9: 1 | R9: =SUM(C9:Q9) -> 2
A10: CLINICA SANATORIO ALEMAN S.A | K10: 1 | R10: =SUM(C10:Q10) -> 1
A11: CONSULTORIO GENERAL URBANO VIOLETA PARRA | R11: =SUM(C11:Q11) -> 0
A12: CORPORACION IGLESIA ADVENTISTA DEL 7Â° DIA | R12: =SUM(C12:Q12) -> 0
A13: DIRECCION DE SALUD MUNICIPAL DE TOME | D13: 1 | R13: =SUM(C13:Q13) -> 1
A14: DIRECCION DE SALUD SAN PEDRO DE LA PAZ | R14: =SUM(C14:Q14) -> 0
A15: HOSPITAL ANGOL | G15: 1 | R15: =SUM(C15:Q15) -> 1
A16: HOSPITAL ARAUCO | C16: 1 | R16: =SUM(C16:Q16) -> 1
A17: HOSPITAL BASE DR. VICTOR RIOS RUIZ | R17: =SUM(C17:Q17) -> 0
A18: HOSPITAL CAÑETE | C18: 1 | R18: =SUM(C18:Q18) -> 1
A19: HOSPITAL CLINICO DEL SUR | R19: =SUM(C19:Q19) -> 0
A20: HOSPITAL CLINICO HERMINDA MARTIN | H20: 1 | R20: =SUM(C20:Q20) -> 1
A21: HOSPITAL DE CURANILAHUE | C21: 1 | R21: =SUM(C21:Q21) -> 1
A22: HOSPITAL DE PENCO | D22: 1 | R22: =SUM(C22:Q22) -> 1
A23: HOSPITAL DE SAN CARLOS | J23: 1 | R23: =SUM(C23:Q23) -> 1
A24: HOSPITAL DE TOME | D24: 1 | R24: =SUM(C24:Q24) -> 1
A25: HOSPITAL GUILLERMO GRANT BENAVENTE | R25: =SUM(C25:Q25) -> 0
A26: HOSPITAL LAS HIGUERAS | D26: 1 | P26: 1 | R26: =SUM(C26:Q26) -> 2
A27: HOSPITAL LEBU | C27: 1 | R27: =SUM(C27:Q27) -> 1
A28: HOSPITAL LOTA | M28: 1 | R28: =SUM(C28:Q28) -> 1
A29: HOSPITAL NAVAL TALCAHUANO A.A. | P29: 1 | R29: =SUM(C29:Q29) -> 1
A30: HOSPITAL SAN JOSE DE CORONEL | M30: 1 | R30: =SUM(C30:Q30) -> 1
A31: HOSPITAL TRAUMATOLOGICO DE CONCEPCION | R31: =SUM(C31:Q31) -> 0
A32: I MUNICIPALIDAD DE ANGOL | G32: 1 | R32: =SUM(C32:Q32) -> 1
A33: I MUNICIPALIDAD DE CABRERO DEPARTAMENTO DE SALUD | G33: 1 | R33: =SUM(C33:Q33) -> 1
A34: I MUNICIPALIDAD DE CORONEL DPTO ADMINIST | M34: 1 | R34: =SUM(C34:Q34) -> 1
A35: I MUNICIPALIDAD DE LOTA DEPARTAMENTO DE SALUD | M35: 1 | R35: =SUM(C35:Q35) -> 1
A36: I MUNICIPALIDAD DE TALCAHUANO | P36: 1 | R36: =SUM(C36:Q36) -> 1
A37: ILUSTRE MUNICIPALIDAD DE CHIGUAYANTE | K37: 1 | R37: =SUM(C37:Q37) -> 1
A38: ILUSTRE MUNICIPALIDAD DE CHILLAN DPTO SALUD | F38: 1 | R38: =SUM(C38:Q38) -> 1
A39: ILUSTRE MUNICIPALIDAD DE CHILLAN VIEJO | E39: 1 | H39: 2 | I39: 1 | R39: =SUM(C39:Q39) -> 4
A40: MUNICIPALIDAD DE CONCEPCION | R40: =SUM(C40:Q40) -> 0
A41: MUNICIPALIDAD DE HUALPEN | P41: 1 | R41: =SUM(C41:Q41) -> 1
...

Sheet clientes no en sap
A1: 45008673 | B1: CLAUDIO ALVAREZ URRA | C1: SANTIAGO | D1: 13 | E1: ATENCION TELEFONICA | F1: ="CN"&LEFT(Tabla13[[#This Row],[RUT]],LEN(Tabla13[[#This Row],[RUT]]-1)) -> #VALUE! | G1: PRIVADO | H1: ATEL | I1: REGIÓN DE METROPOLITANA DE SANTIAGO
A2: 118464397 | B2: CARLOS IGNACIO ARANCIBIA BARRENECHEA | C2: SANTIAGO | D2: 13 | E2: ATENCION TELEFONICA | F2: ="CN"&LEFT(Tabla13[[#This Row],[RUT]],LEN(Tabla13[[#This Row],[RUT]])-1) -> CN3517865 | G2: PRIVADO | H2: ATEL | I2: REGIÓN DE METROPOLITANA DE SANTIAGO
A3: 602020002 | B3: CAMARA DE DIPUTADOS DE CHILE | C3: VALPARAÍSO | D3: 5 | E3: ATENCION TELEFONICA | F3: ="CN"&LEFT(Tabla13[[#This Row],[RUT]],LEN(Tabla13[[#This Row],[RUT]])-1) -> CN3753123 | G3: PÚBLICO | H3: ATEL | I3: REGIÓN DE VALPARAÍSO
A4: 611021275 | B4: CENTRO DE INSTRUCCION Y CAPACITACION MARITIMA | C4: VALPARAÍSO | D4: 5 | E4: ATENCION TELEFONICA | F4: ="CN"&LEFT(Tabla13[[#This Row],[RUT]],LEN(Tabla13[[#This Row],[RUT]])-1) -> CN4500867 | G4: PRIVADO | H4: ATEL | I4: REGIÓN DE VALPARAÍSO
A5: 611030215 | B5: Ivª Brigada Aérea | C5: PUNTA ARENAS | D5: 12 | E5: ATENCION TELEFONICA | F5: ="CN"&LEFT(Tabla13[[#This Row],[RUT]],LEN(Tabla13[[#This Row],[RUT]])-1) -> CN5077288 | G5: PÚBLICO | H5: ATEL | I5: REGIÓN DE MAGALLANES Y DE LA ANTÁRTICA CHILENA
A6: 619742001 | B6: EJERCITO DE CHILE | C6: SANTIAGO | D6: 13 | E6: ATENCION TELEFONICA | F6: ="CN"&LEFT(Tabla13[[#This Row],[RUT]],LEN(Tabla13[[#This Row],[RUT]])-1) -> CN5320819 | G6: PÚBLICO | H6: ATEL | I6: REGIÓN DE METROPOLITANA DE SANTIAGO
A7: 619992806 | B7: CENTRO DE FORMACION TECNICA DE LA REGION DE COQUIMBO | C7: COQUIMBO | D7: 4 | E7: ATENCION TELEFONICA | F7: ="CN"&LEFT(Tabla13[[#This Row],[RUT]],LEN(Tabla13[[#This Row],[RUT]])-1) -> CN6389002 | G7: PRIVADO | H7: ATEL | I7: REGIÓN DE COQUIMBO
A8: 620008907 | B8: Servicio Nacional De Protección Especializada A La Niñez Y Adolescenci | C8: CONCEPCIÓN | D8: 8 | E8: ATENCION TELEFONICA | F8: ="CN"&LEFT(Tabla13[[#This Row],[RUT]],LEN(Tabla13[[#This Row],[RUT]])-1) -> CN6412721 | G8: PÚBLICO | H8: ATEL | I8: REGIÓN DE BIOBÍO
A9: 651455669 | B9: COLEGIO AMERICANO CE | C9: LA SERENA | D9: 4 | E9: ATENCION TELEFONICA | F9: ="CN"&LEFT(Tabla13[[#This Row],[RUT]],LEN(Tabla13[[#This Row],[RUT]])-1) -> CN6490320 | G9: PRIVADO | H9: ATEL | I9: REGIÓN DE COQUIMBO
A10: 651543983 | B10: CENTRO DE FORMACION TECNICA DE LA REGION DE TARAPA | C10: IQUIQUE | D10: 1 | E10: ATENCION TELEFONICA | F10: ="CN"&LEFT(Tabla13[[#This Row],[RUT]],LEN(Tabla13[[#This Row],[RUT]])-1) -> CN7303109 | G10: PRIVADO | H10: ATEL | I10: REGIÓN DE TARAPACÁ
A11: 651654114 | B11: CENTRO DE FORMACION TECNICA ESTATAL DE LA REGION DE VALPARAISO | C11: VIÑA DEL MAR | D11: 5 | E11: ATENCION TELEFONICA | F11: ="CN"&LEFT(Tabla13[[#This Row],[RUT]],LEN(Tabla13[[#This Row],[RUT]])-1) -> CN7918692 | G11: PÚBLICO | H11: ATEL | I11: REGIÓN DE VALPARAÍSO
A12: 654556504 | B12: Ejercito De Chile | C12: ANTOFAGASTA | D12: 2 | E12: ATENCION TELEFONICA | F12: ="CN"&LEFT(Tabla13[[#This Row],[RUT]],LEN(Tabla13[[#This Row],[RUT]])-1) -> CN8181832 | G12: PÚBLICO | H12: ATEL | I12: REGIÓN DE ANTOFAGASTA
A13: 692532007 | B13: I Municipalidad De Sierra Gorda | C13: SIERRA GORDA | D13: 2 | E13: ATENCION TELEFONICA | F13: ="CN"&LEFT(Tabla13[[#This Row],[RUT]],LEN(Tabla13[[#This Row],[RUT]])-1) -> CN8185029 | G13: PÚBLICO | H13: ATEL | I13: REGIÓN DE ANTOFAGASTA
... A32: 995240300 | B32: CENTRO RENAL SPA | C32: QUILPUÉ | D32: 5 | E32: ATENCION TELEFONICA | F32: ="CN"&LEFT(Tabla13[[#This Row],[RUT]],LEN(Tabla13[[#This Row],[RUT]])-1) -> CN23645146 | G32: PRIVADO | H32: ATEL | I32: REGIÓN DE VALPARAÍSO
A33: 61102004K | B33: Dirección De Abastecimiento De La Armada | C33: ALGARROBO | D33: 5 | E33: ATENCION TELEFONICA | F33: ="CN"&LEFT(Tabla13[[#This Row],[RUT]],LEN(Tabla13[[#This Row],[RUT]])-1) -> CN25952636 | G33: PRIVADO | H33: ATEL | I33: REGIÓN DE VALPARAÍSO
A34: 77326113K | B34: CLINICA DENTAL ROJOS SPA | C34: COPIAPÓ | D34: 3 | E34: ATENCION TELEFONICA | F34: ="CN"&LEFT(Tabla13[[#This Row],[RUT]],LEN(Tabla13[[#This Row],[RUT]])-1) -> CN59077290 | G34: PRIVADO | H34: ATEL | I34: REGIÓN DE ATACAMA
A35: 77849650K | B35: CLINICA Y CENTRO MEDICO DELGADO LTDA | C35: SANTIAGO | D35: 13 | E35: ATENCION TELEFONICA | F35: ="CN"&LEFT(Tabla13[[#This Row],[RUT]],LEN(Tabla13[[#This Row],[RUT]])-1) -> CN60103000 | G35: PRIVADO | H35: ATEL | I35: REGIÓN DE METROPOLITANA DE SANTIAGO
A36: 78464300K | B36: COMERCIAL SERVICOPIER SPA | C36: SANTIAGO | D36: 13 | E36: ATENCION TELEFONICA | F36: ="CN"&LEFT(Tabla13[[#This Row],[RUT]],LEN(Tabla13[[#This Row],[RUT]])-1) -> CN60202000 | G36: PRIVADO | H36: ATEL | I36: REGIÓN DE METROPOLITANA DE SANTIAGO
A37: 774097899 | B37: CALEMA SPA | C37: SANTIAGO | D37: 13 | E37: ATENCION TELEFONICA | F37: ="CN"&LEFT(Tabla13[[#This Row],[RUT]],LEN(Tabla13[[#This Row],[RUT]])-1) -> CN60506000 | G37: PRIVADO | H37: ATEL | I37: REGIÓN DE METROPOLITANA DE SANTIAGO

Sheet CARTERA 2025
A1: RUT | B1: RAZON | C1: COMUNA | D1: REGION | E1: VENDEDOR | F1: COD CLIENTE | G1: INDUSTRIA | H1: SECTOR | I1: CARTERA | J1: REGION NOMBRE
A2: 35178651 | B2: FRANCISCO CAMPOS SANHUEZA | D2: 13 | E2: ATENCION TELEFONICA | F2: CN3517865 | I2: =IF(Tabla13[[#This Row],[RUT]]=774097899,"DIST",_xlfn.XLOOKUP(Tabla13[[#This Row],[VENDEDOR]],dimensiones!$C$21:$C$28,dimensiones!$D$21:$D$28,"")) -> ATEL | J2: =_xlfn.XLOOKUP(Tabla13[[#This Row],[REGION]],dimensiones!C:C,dimensiones!D:D,"") -> Región de Metropolitana de Santiago
A3: 37531235 | B3: ANA ABURDENE | D3: 16 | E3: ATENCION TELEFONICA | F3: CN3753123 | I3: =IF(Tabla13[[#This Row],[RUT]]=774097899,"DIST",_xlfn.XLOOKUP(Tabla13[[#This Row],[VENDEDOR]],dimensiones!$C$21:$C$28,dimensiones!$D$21:$D$28,"")) -> ATEL | J3: =_xlfn.XLOOKUP(Tabla13[[#This Row],[REGION]],dimensiones!C:C,dimensiones!D:D,"") -> Región de Ñuble
A4: 45008673 | B4: CLAUDIO ALVAREZ URRA | C4: SANTIAGO | D4: 13 | E4: ATENCION TELEFONICA | F4: CN4500867 | H4: PRIVADO | I4: =IF(Tabla13[[#This Row],[RUT]]=774097899,"DIST",_xlfn.XLOOKUP(Tabla13[[#This Row],[VENDEDOR]],dimensiones!$C$21:$C$28,dimensiones!$D$21:$D$28,"")) -> ATEL | J4: =_xlfn.XLOOKUP(Tabla13[[#This Row],[REGION]],dimensiones!C:C,dimensiones!D:D,"") -> Región de Metropolitana de Santiago
A5: 50772888 | B5: TERESA DE JESUS ANDRADE ZELADA | D5: 13 | E5: ATENCION TELEFONICA | F5: CN5077288 | I5: =IF(Tabla13[[#This Row],[RUT]]=774097899,"DIST",_xlfn.XLOOKUP(Tabla13[[#This Row],[VENDEDOR]],dimensiones!$C$21:$C$28,dimensiones!$D$21:$D$28,"")) -> ATEL | J5: =_xlfn.XLOOKUP(Tabla13[[#This Row],[REGION]],dimensiones!C:C,dimensiones!D:D,"") -> Región de Metropolitana de Santiago
A6: 53208193 | B6: BELARMINO SEGUNDO DONOSO FUENTES | D6: 13 | E6: ATENCION TELEFONICA | F6: CN5320819 | I6: =IF(Tabla13[[#This Row],[RUT]]=774097899,"DIST",_xlfn.XLOOKUP(Tabla13[[#This Row],[VENDEDOR]],dimensiones!$C$21:$C$28,dimensiones!$D$21:$D$28,"")) -> ATEL | J6: =_xlfn.XLOOKUP(Tabla13[[#This Row],[REGION]],dimensiones!C:C,dimensiones!D:D,"") -> Región de Metropolitana de Santiago
A7: 63890022 | B7: ELIAS CORDOVA RUIZ | D7: 4 | E7: ATENCION TELEFONICA | F7: CN6389002 | I7: =IF(Tabla13[[#This Row],[RUT]]=774097899,"DIST",_xlfn.XLOOKUP(Tabla13[[#This Row],[VENDEDOR]],dimensiones!$C$21:$C$28,dimensiones!$D$21:$D$28,"")) -> ATEL | J7: =_xlfn.XLOOKUP(Tabla13[[#This Row],[REGION]],dimensiones!C:C,dimensiones!D:D,"") -> Región de Coquimbo
A8: 64127217 | B8: DOCTOR SERGIO MAYORGA CIOCCA | D8: 13 | E8: ATENCION TELEFONICA | F8: CN6412721 | I8: =IF(Tabla13[[#This Row],[RUT]]=774097899,"DIST",_xlfn.XLOOKUP(Tabla13[[#This Row],[VENDEDOR]],dimensiones!$C$21:$C$28,dimensiones!$D$21:$D$28,"")) -> ATEL | J8: =_xlfn.XLOOKUP(Tabla13[[#This Row],[REGION]],dimensiones!C:C,dimensiones!D:D,"") -> Región de Metropolitana de Santiago
A9: 64903209 | B9: VICTOR MANUEL BORJE ARAYA | D9: 13 | E9: ATENCION TELEFONICA | F9: CN6490320 | I9: =IF(Tabla13[[#This Row],[RUT]]=774097899,"DIST",_xlfn.XLOOKUP(Tabla13[[#This Row],[VENDEDOR]],dimensiones!$C$21:$C$28,dimensiones!$D$21:$D$28,"")) -> ATEL | J9: =_xlfn.XLOOKUP(Tabla13[[#This Row],[REGION]],dimensiones!C:C,dimensiones!D:D,"") -> Región de Metropolitana de Santiago
A10: 73031095 | B10: JUAN A. RAMIREZ CASTILLO | D10: 9 | E10: ATENCION TELEFONICA | F10: CN7303109 | I10: =IF(Tabla13[[#This Row],[RUT]]=774097899,"DIST",_xlfn.XLOOKUP(Tabla13[[#This Row],[VENDEDOR]],dimensiones!$C$21:$C$28,dimensiones!$D$21:$D$28,"")) -> ATEL | J10: =_xlfn.XLOOKUP(Tabla13[[#This Row],[REGION]],dimensiones!C:C,dimensiones!D:D,"") -> Región de La Araucanía
A11: 79186929 | B11: MANUEL EDUARDO VIDAL BARRIA | D11: 8 | E11: ATENCION TELEFONICA | F11: CN7918692 | I11: =IF(Tabla13[[#This Row],[RUT]]=774097899,"DIST",_xlfn.XLOOKUP(Tabla13[[#This Row],[VENDEDOR]],dimensiones!$C$21:$C$28,dimensiones!$D$21:$D$28,"")) -> ATEL | J11: =_xlfn.XLOOKUP(Tabla13[[#This Row],[REGION]],dimensiones!C:C,dimensiones!D:D,"") -> Región de Biobío
A12: 81818320 | B12: LEOCADIA GONZALEZ TORO | D12: 14 | E12: ATENCION TELEFONICA | F12: CN8181832 | I12: =IF(Tabla13[[#This Row],[RUT]]=774097899,"DIST",_xlfn.XLOOKUP(Tabla13[[#This Row],[VENDEDOR]],dimensiones!$C$21:$C$28,dimensiones!$D$21:$D$28,"")) -> ATEL | J12: =_xlfn.XLOOKUP(Tabla13[[#This Row],[REGION]],dimensiones!C:C,dimensiones!D:D,"") -> Región de Los Ríos
A13: 81850291 | B13: ISABEL LEIVA FUENTEALBA | D13: 16 | E13: ATENCION TELEFONICA | F13: CN8185029 | I13: =IF(Tabla13[[#This Row],[RUT]]=774097899,"DIST",_xlfn.XLOOKUP(Tabla13[[#This Row],[VENDEDOR]],dimensiones!$C$21:$C$28,dimensiones!$D$21:$D$28,"")) -> ATEL | J13: =_xlfn.XLOOKUP(Tabla13[[#This Row],[REGION]],dimensiones!C:C,dimensiones!D:D,"") -> Región de Ñuble
A14: 81853363 | B14: ARTURO GUTIERREZ RUBILAR | D14: 9 | E14: ATENCION TELEFONICA | F14: CN8185336 | I14: =IF(Tabla13[[#This Row],[RUT]]=774097899,"DIST",_xlfn.XLOOKUP(Tabla13[[#This Row],[VENDEDOR]],dimensiones!$C$21:$C$28,dimensiones!$D$21:$D$28,"")) -> ATEL | J14: =_xlfn.XLOOKUP(Tabla13[[#This Row],[REGION]],dimensiones!C:C,dimensiones!D:D,"") -> Región de La Araucanía
A15: 88248228 | B15: ERIKA IVONNE CACERES PAVEZ | D15: 13 | E15: ATENCION TELEFONICA | F15: CN8824822 | I15: =IF(Tabla13[[#This Row],[RUT]]=774097899,"DIST",_xlfn.XLOOKUP(Tabla13[[#This Row],[VENDEDOR]],dimensiones!$C$21:$C$28,dimensiones!$D$21:$D$28,"")) -> ATEL | J15: =_xlfn.XLOOKUP(Tabla13[[#This Row],[REGION]],dimensiones!C:C,dimensiones!D:D,"") -> Región de Metropolitana de Santiago
A16: 91511959 | B16: FRANCISCO JAVIER PARDO QUIROZ | D16: 13 | E16: ATENCION TELEFONICA | F16: CN9151195 | I16: =IF(Tabla13[[#This Row],[RUT]]=774097899,"DIST",_xlfn.XLOOKUP(Tabla13[[#This Row],[VENDEDOR]],dimensiones!$C$21:$C$28,dimensiones!$D$21:$D$28,"")) -> ATEL | J16: =_xlfn.XLOOKUP(Tabla13[[#This Row],[REGION]],dimensiones!C:C,dimensiones!D:D,"") -> Región de Metropolitana de Santiago
... A19: 106711038 | B19: ROSA BURGOS DOMINGUEZ | D19: 3 | E19: ATENCION TELEFONICA | F19: CN10671103 | I19: =IF(Tabla13[[#This Row],[RUT]]=774097899,"DIST",_xlfn.XLOOKUP(Tabla13[[#This Row],[VENDEDOR]],dimensiones!$C$21:$C$28,dimensiones!$D$21:$D$28,"")) -> ATEL | J19: =_xlfn.XLOOKUP(Tabla13[[#This Row],[REGION]],dimensiones!C:C,dimensiones!D:D,"") -> Región de Atacama
A20: 118464397 | B20: CARLOS IGNACIO ARANCIBIA BARRENECHEA | C20: SANTIAGO | D20: 13 | E20: ATENCION TELEFONICA | F20: CN11846439 | H20: PRIVADO | I20: =IF(Tabla13[[#This Row],[RUT]]=774097899,"DIST",_xlfn.XLOOKUP(Tabla13[[#This Row],[VENDEDOR]],dimensiones!$C$21:$C$28,dimensiones!$D$21:$D$28,"")) -> ATEL | J20: =_xlfn.XLOOKUP(Tabla13[[#This Row],[REGION]],dimensiones!C:C,dimensiones!D:D,"") -> Región de Metropolitana de Santiago
A21: 118726197 | B21: PAULA ANDREA RIVERA BRUNET | D21: 8 | E21: ATENCION TELEFONICA | F21: CN11872619 | I21: =IF(Tabla13[[#This Row],[RUT]]=774097899,"DIST",_xlfn.XLOOKUP(Tabla13[[#This Row],[VENDEDOR]],dimensiones!$C$21:$C$28,dimensiones!$D$21:$D$28,"")) -> ATEL | J21: =_xlfn.XLOOKUP(Tabla13[[#This Row],[REGION]],dimensiones!C:C,dimensiones!D:D,"") -> Región de Biobío
A22: 121317834 | B22: HECTOR CARRENO BAEZA | D22: 13 | E22: ATENCION TELEFONICA | F22: CN12131783 | I22: =IF(Tabla13[[#This Row],[RUT]]=774097899,"DIST",_xlfn.XLOOKUP(Tabla13[[#This Row],[VENDEDOR]],dimensiones!$C$21:$C$28,dimensiones!$D$21:$D$28,"")) -> ATEL | J22: =_xlfn.XLOOKUP(Tabla13[[#This Row],[REGION]],dimensiones!C:C,dimensiones!D:D,"") -> Región de Metropolitana de Santiago
A23: 122836576 | B23: MARGARITA RAILEN | D23: 13 | E23: ATENCION TELEFONICA | F23: CN12283657 | I23: =IF(Tabla13[[#This Row],[RUT]]=774097899,"DIST",_xlfn.XLOOKUP(Tabla13[[#This Row],[VENDEDOR]],dimensiones!$C$21:$C$28,dimensiones!$D$21:$D$28,"")) -> ATEL | J23: =_xlfn.XLOOKUP(Tabla13[[#This Row],[REGION]],dimensiones!C:C,dimensiones!D:D,"") -> Región de Metropolitana de Santiago
A24: 150855403 | B24: ANDRES REYES | D24: 5 | E24: ATENCION TELEFONICA | F24: CN15085540 | I24: =IF(Tabla13[[#This Row],[RUT]]=774097899,"DIST",_xlfn.XLOOKUP(Tabla13[[#This Row],[VENDEDOR]],dimensiones!$C$21:$C$28,dimensiones!$D$21:$D$28,"")) -> ATEL | J24: =_xlfn.XLOOKUP(Tabla13[[#This Row],[REGION]],dimensiones!C:C,dimensiones!D:D,"") -> Región de Valparaíso
A25: 161447579 | B25: IVAN CARLOS CANDIA ALDAY | D25: 13 | E25: ATENCION TELEFONICA | F25: CN16144757 | I25: =IF(Tabla13[[#This Row],[RUT]]=774097899,"DIST",_xlfn.XLOOKUP(Tabla13[[#This Row],[VENDEDOR]],dimensiones!$C$21:$C$28,dimensiones!$D$21:$D$28,"")) -> ATEL | J25: =_xlfn.XLOOKUP(Tabla13[[#This Row],[REGION]],dimensiones!C:C,dimensiones!D:D,"") -> Región de Metropolitana de Santiago
A26: 165289676 | B26: MARCO ANTONIO ALBORNOZ SOTO | D26: 6 | E26: ATENCION TELEFONICA | F26: CN16528967 | I26: =IF(Tabla13[[#This Row],[RUT]]=774097899,"DIST",_xlfn.XLOOKUP(Tabla13[[#This Row],[VENDEDOR]],dimensiones!$C$21:$C$28,dimensiones!$D$21:$D$28,"")) -> ATEL | J26: =_xlfn.XLOOKUP(Tabla13[[#This Row],[REGION]],dimensiones!C:C,dimensiones!D:D,"") -> Región de Libertador General Bernardo O'Higgins
A27: 173054734 | B27: ANDREA LUPAYANTE LUPAYÀNTE | D27: 13 | E27: ATENCION TELEFONICA | F27: CN17305473 | I27: =IF(Tabla13[[#This Row],[RUT]]=774097899,"DIST",_xlfn.XLOOKUP(Tabla13[[#This Row],[VENDEDOR]],dimensiones!$C$21:$C$28,dimensiones!$D$21:$D$28,"")) -> ATEL | J27: =_xlfn.XLOOKUP(Tabla13[[#This Row],[REGION]],dimensiones!C:C,dimensiones!D:D,"") -> Región de Metropolitana de Santiago
A28: 176056827 | B28: JUAN ANDRES DIAZ GOMEZ | D28: 8 | E28: ATENCION TELEFONICA | F28: CN17605682 | I28: =IF(Tabla13[[#This Row],[RUT]]=774097899,"DIST",_xlfn.XLOOKUP(Tabla13[[#This Row],[VENDEDOR]],dimensiones!$C$21:$C$28,dimensiones!$D$21:$D$28,"")) -> ATEL | J28: =_xlfn.XLOOKUP(Tabla13[[#This Row],[REGION]],dimensiones!C:C,dimensiones!D:D,"") -> Región de Biobío
A29: 176445467 | B29: HUMBERTO MIERES MORALES | D29: 13 | E29: ATENCION TELEFONICA | F29: CN17644546 | I29: =IF(Tabla13[[#This Row],[RUT]]=774097899,"DIST",_xlfn.XLOOKUP(Tabla13[[#This Row],[VENDEDOR]],dimensiones!$C$21:$C$28,dimensiones!$D$21:$D$28,"")) -> ATEL | J29: =_xlfn.XLOOKUP(Tabla13[[#This Row],[REGION]],dimensiones!C:C,dimensiones!D:D,"") -> Región de Metropolitana de Santiago
A30: 180567933 | B30: LEONARDO QUEZADA VERGARA | D30: 13 | E30: ATENCION TELEFONICA | F30: CN18056793 | I30: =IF(Tabla13[[#This Row],[RUT]]=774097899,"DIST",_xlfn.XLOOKUP(Tabla13[[#This Row],[VENDEDOR]],dimensiones!$C$21:$C$28,dimensiones!$D$21:$D$28,"")) -> ATEL | J30: =_xlfn.XLOOKUP(Tabla13[[#This Row],[REGION]],dimensiones!C:C,dimensiones!D:D,"") -> Región de Metropolitana de Santiago
A31: 188563619 | B31: JAVIER EDUARDO FLORES GOMEZ | D31: 3 | E31: ATENCION TELEFONICA | F31: CN18856361 | I31: =IF(Tabla13[[#This Row],[RUT]]=774097899,"DIST",_xlfn.XLOOKUP(Tabla13[[#This Row],[VENDEDOR]],dimensiones!$C$21:$C$28,dimensiones!$D$21:$D$28,"")) -> ATEL | J31: =_xlfn.XLOOKUP(Tabla13[[#This Row],[REGION]],dimensiones!C:C,dimensiones!D:D,"") -> Región de Atacama
A32: 236451461 | B32: ANA MARIA TICONA APANA | D32: 13 | E32: ATENCION TELEFONICA | F32: CN23645146 | I32: =IF(Tabla13[[#This Row],[RUT]]=774097899,"DIST",_xlfn.XLOOKUP(Tabla13[[#This Row],[VENDEDOR]],dimensiones!$C$21:$C$28,dimensiones!$D$21:$D$28,"")) -> ATEL | J32: =_xlfn.XLOOKUP(Tabla13[[#This Row],[REGION]],dimensiones!C:C,dimensiones!D:D,"") -> Región de Metropolitana de Santiago
... A35: 601030004 | B35: SUBSECRETARIA DE SERVICIOS SOCIALES | D35: 13 | E35: ATENCION TELEFONICA | F35: CN60103000 | I35: =IF(Tabla13[[#This Row],[RUT]]=774097899,"DIST",_xlfn.XLOOKUP(Tabla13[[#This Row],[VENDEDOR]],dimensiones!$C$21:$C$28,dimensiones!$D$21:$D$28,"")) -> ATEL | J35: =_xlfn.XLOOKUP(Tabla13[[#This Row],[REGION]],dimensiones!C:C,dimensiones!D:D,"") -> Región de Metropolitana de Santiago
A36: 602020002 | B36: CAMARA DE DIPUTADOS DE CHILE | C36: VALPARAÍSO | D36: 5 | E36: ATENCION TELEFONICA | F36: CN60202000 | H36: PÚBLICO | I36: =IF(Tabla13[[#This Row],[RUT]]=774097899,"DIST",_xlfn.XLOOKUP(Tabla13[[#This Row],[VENDEDOR]],dimensiones!$C$21:$C$28,dimensiones!$D$21:$D$28,"")) -> ATEL | J36: =_xlfn.XLOOKUP(Tabla13[[#This Row],[REGION]],dimensiones!C:C,dimensiones!D:D,"") -> Región de Valparaíso
A37: 605060005 | B37: POLICIA DE INVESTIGACIONES DE CHILE | D37: 10 | E37: ATENCION TELEFONICA | F37: CN60506000 | I37: =IF(Tabla13[[#This Row],[RUT]]=774097899,"DIST",_xlfn.XLOOKUP(Tabla13[[#This Row],[VENDEDOR]],dimensiones!$C$21:$C$28,dimensiones!$D$21:$D$28,"")) -> ATEL | J37: =_xlfn.XLOOKUP(Tabla13[[#This Row],[REGION]],dimensiones!C:C,dimensiones!D:D,"") -> Región de Los Lagos
A38: 605060129 | B38: ESCUELA DE INVESTIGACIONES POLICIALES (ESCIPOL) | D38: 13 | E38: ATENCION TELEFONICA | F38: CN60506012 | I38: =IF(Tabla13[[#This Row],[RUT]]=774097899,"DIST",_xlfn.XLOOKUP(Tabla13[[#This Row],[VENDEDOR]],dimensiones!$C$21:$C$28,dimensiones!$D$21:$D$28,"")) -> ATEL | J38: =_xlfn.XLOOKUP(Tabla13[[#This Row],[REGION]],dimensiones!C:C,dimensiones!D:D,"") -> Región de Metropolitana de Santiago
A39: 605111300 | B39: INTENDENCIA REGION METROPOLITANA | D39: 13 | E39: ATENCION TELEFONICA | F39: CN60511130 | I39: =IF(Tabla13[[#This Row],[RUT]]=774097899,"DIST",_xlfn.XLOOKUP(Tabla13[[#This Row],[VENDEDOR]],dimensiones!$C$21:$C$28,dimensiones!$D$21:$D$28,"")) -> ATEL | J39: =_xlfn.XLOOKUP(Tabla13[[#This Row],[REGION]],dimensiones!C:C,dimensiones!D:D,"") -> Región de Metropolitana de Santiago
A40: 609020636 | B40: ILUSTRE MUNICIPALIDAD DE LINARES | D40: 7 | E40: ATENCION TELEFONICA | F40: CN60902063 | I40: =IF(Tabla13[[#This Row],[RUT]]=774097899,"DIST",_xlfn.XLOOKUP(Tabla13[[#This Row],[VENDEDOR]],dimensiones!$C$21:$C$28,dimensiones!$D$21:$D$28,"")) -> ATEL | J40: =_xlfn.XLOOKUP(Tabla13[[#This Row],[REGION]],dimensiones!C:C,dimensiones!D:D,"") -> Región de Maule
A41: 609050004 | B41: SERVICIO NACIONAL DEL PATRIMONIO CULTURAL | D41: 4 | E41: ATENCION TELEFONICA | F41: CN60905000 | I41: =IF(Tabla13[[#This Row],[RUT]]=774097899,"DIST",_xlfn.XLOOKUP(Tabla13[[#This Row],[VENDEDOR]],dimensiones!$C$21:$C$28,dimensiones!$D$21:$D$28,"")) -> ATEL | J41: =_xlfn.XLOOKUP(Tabla13[[#This Row],[REGION]],dimensiones!C:C,dimensiones!D:D,"") -> Región de Coquimbo
A42: 609100478 | B42: UNIVERSIDAD METROPOLITANA DE CIENCIAS DE LA EDUCACION | D42: 13 | E42: ATENCION TELEFONICA | F42: CN60910047 | I42: =IF(Tabla13[[#This Row],[RUT]]=774097899,"DIST",_xlfn.XLOOKUP(Tabla13[[#This Row],[VENDEDOR]],dimensiones!$C$21:$C$28,dimensiones!$D$21:$D$28,"")) -> ATEL | J42: =_xlfn.XLOOKUP(Tabla13[[#This Row],[REGION]],dimensiones!C:C,dimensiones!D:D,"") -> Región de Metropolitana de Santiago
A43: 609110066 | B43: UNIVERSIDAD DEL BIO BIO | D43: 8 | E43: ATENCION TELEFONICA | F43: CN60911006 | I43: =IF(Tabla13[[#This Row],[RUT]]=774097899,"DIST",_xlfn.XLOOKUP(Tabla13[[#This Row],[VENDEDOR]],dimensiones!$C$21:$C$28,dimensiones!$D$21:$D$28,"")) -> ATEL | J43: =_xlfn.XLOOKUP(Tabla13[[#This Row],[REGION]],dimensiones!C:C,dimensiones!D:D,"") -> Región de Biobío
A44: 610040071 | B44: DIRECCION REGIONAL DE GENDARMERIA - ANTOFAGASTA | D44: 2 | E44: ATENCION TELEFONICA | F44: CN61004007 | I44: =IF(Tabla13[[#This Row],[RUT]]=774097899,"DIST",_xlfn.XLOOKUP(Tabla13[[#This Row],[VENDEDOR]],dimensiones!$C$21:$C$28,dimensiones!$D$21:$D$28,"")) -> ATEL | J44: =_xlfn.XLOOKUP(Tabla13[[#This Row],[REGION]],dimensiones!C:C,dimensiones!D:D,"") -> Región de Antofagasta
...

Sheet CARTERA 2025 (2)
A1: RUT | B1: RAZON | C1: VENDEDOR | D1: CARTERA | E1: COMUNA | F1: REGION | G1: COD CLIENTE | H1: RUT SD | I1: SECTOR | J1: prueba | L1: Nota: Se actualizo la cartera 2025, sin embargo, cartera de SANTIAGO III Y SUR III pasan a atencion telefonica ya que no tienen vendedor.
A2: 616080024 | B2: HOSPITAL SAN JOSE | C2: M RAMOS | D2: SANTIAGO II | E2: INDEPENDENCIA | F2: REGIÓN DE METROPOLITANA DE SANTIAGO | G2: CN61608002 | H2: 61608002 | I2: PUBLICO | J2: MAURICIO RAMOS MORENO
A3: 703601006 | B3: ASOCIACION CHILENA DE SEGURIDAD | C3: A TELEFONICA | D3: A TELEFONICA | E3: PROVIDENCIA | F3: REGIÓN DE METROPOLITANA DE SANTIAGO | G3: CN70360100 | H3: 70360100 | I3: PRIVADO | J3: ATENCION TELEFONICA
A4: 616086022 | B4: HOSPITAL DE URGENCIA ASISTENCIA PUBLICA | C4: G MANNESCHI | D4: SANTIAGO I | E4: SANTIAGO | F4: REGIÓN DE METROPOLITANA DE SANTIAGO | G4: CN61608602 | H4: 61608602 | I4: PUBLICO | J4: GIANCARLO MANNESCHI GALLARDO
A5: 619751000 | B5: HOSPITAL DE PUERTO MONTT | C5: M RUIZ | D5: SUR II | E5: PUERTO MONTT | F5: REGIÓN DE LOS LAGOS | G5: CN61975100 | H5: 61975100 | I5: PUBLICO | J5: MARCELO RUIZ
A6: 616021893 | B6: HOSPITAL GUILLERMO GRANT BENAVENTE | C6: R ARAYA | D6: SUR I | E6: HUALPÉN | F6: REGIÓN DE BIOBÍO | G6: CN61602189 | H6: 61602189 | I6: PUBLICO | J6: RICARDO ENRIQUE ARAYA GONZÁLEZ
A7: 616020544 | B7: HOSPITAL CARLOS VAN BUREN | C7: C VALENZUELA | D7: NORTE I | E7: VALPARAÍSO | F7: REGIÓN DE VALPARAÍSO | G7: CN61602054 | H7: 61602054 | I7: PUBLICO | J7: CONSTANZA VALENZUELA
A8: 616082043 | B8: HOSPITAL SAN JUAN DE DIOS | C8: G MANNESCHI | D8: SANTIAGO I | E8: SANTIAGO | F8: REGIÓN DE METROPOLITANA DE SANTIAGO | G8: CN61608204 | H8: 61608204 | I8: PUBLICO | J8: GIANCARLO MANNESCHI GALLARDO
A9: 619803205 | B9: HOSPITAL CLINICO METROPOLITANO EL CARMEN DOCTOR LUIS VALENTIN FERRADA | C9: G MANNESCHI | D9: SANTIAGO I | E9: MAIPÚ | F9: REGIÓN DE METROPOLITANA DE SANTIAGO | G9: CN61980320 | H9: 61980320 | I9: PUBLICO | J9: GIANCARLO MANNESCHI GALLARDO
A10: 616086049 | B10: HOSPITAL CLINICO SAN BORJA ARRIARAN | C10: M RAMOS | D10: SANTIAGO II | E10: SANTIAGO | F10: REGIÓN DE METROPOLITANA DE SANTIAGO | G10: CN61608604 | H10: 61608604 | I10: PUBLICO | J10: MAURICIO RAMOS MORENO
A11: 616085026 | B11: COMPLEJO ASISTENCIAL DR. SOTERO DEL RIO | C11: G MANNESCHI | D11: SANTIAGO I | E11: PUENTE ALTO | F11: REGIÓN DE METROPOLITANA DE SANTIAGO | G11: CN61608502 | H11: 61608502 | I11: PUBLICO | J11: GIANCARLO MANNESCHI GALLARDO
A12: 616082051 | B12: HOSPITAL DR. FELIX BULNES CERDA | C12: G MANNESCHI | D12: SANTIAGO I | E12: CERRO NAVIA | F12: REGIÓN DE METROPOLITANA DE SANTIAGO | G12: CN61608205 | H12: 61608205 | I12: PUBLICO | J12: GIANCARLO MANNESCHI GALLARDO
A13: 616066080 | B13: HOSPITAL SAN MARTIN DE QUILLOTA | C13: C VALENZUELA | D13: NORTE I | E13: QUILLOTA | F13: REGIÓN DE VALPARAÍSO | G13: CN61606608 | H13: 61606608 | I13: PUBLICO | J13: CONSTANZA VALENZUELA
... A17: 967701009 | B17: CLINICA ALEMANA | C17: G MANNESCHI | D17: SANTIAGO I | E17: VITACURA | F17: REGIÓN DE METROPOLITANA DE SANTIAGO | G17: CN96770100 | H17: 96770100 | I17: PRIVADO | J17: GIANCARLO MANNESCHI GALLARDO
A18: 61607301K | B18: HOSPITAL BASE DR. VICTOR RIOS RUIZ | C18: R ARAYA | D18: SUR I | E18: LOS ANGELES | F18: REGIÓN DE BIOBÍO | G18: CN61607301 | H18: 61607301 | I18: PUBLICO | J18: RICARDO ENRIQUE ARAYA GONZÁLEZ
A19: 616072021 | B19: HOSPITAL LAS HIGUERAS | C19: R ARAYA | D19: SUR I | E19: TALCAHUANO | F19: REGIÓN DE BIOBÍO | G19: CN61607202 | H19: 61607202 | I19: PUBLICO | J19: RICARDO ENRIQUE ARAYA GONZÁLEZ
A20: 965304703 | B20: CLINICA DAVILA Y SERVICIOS MEDICOS SPA | C20: G MANNESCHI | D20: SANTIAGO I | E20: RECOLETA | F20: REGIÓN DE METROPOLITANA DE SANTIAGO | G20: CN96530470 | H20: 96530470 | I20: PRIVADO | J20: GIANCARLO MANNESCHI GALLARDO
A21: 61103007K | B21: HOSPITAL CLINICO GENERAL DR. RAUL YAZIGI J. | C21: G MANNESCHI | D21: SANTIAGO I | E21: LAS CONDES | F21: REGIÓN DE METROPOLITANA DE SANTIAGO | G21: CN61103007 | H21: 61103007 | I21: PUBLICO | J21: GIANCARLO MANNESCHI GALLARDO
A22: 619598008 | B22: HOSPITAL SANTIAGO ORIENTE DR. LUIS TISNE BROUSSE | C22: G MANNESCHI | D22: SANTIAGO I | E22: PEÑALOLÉN | F22: REGIÓN DE METROPOLITANA DE SANTIAGO | G22: CN61959800 | H22: 61959800 | I22: PUBLICO | J22: GIANCARLO MANNESCHI GALLARDO
A23: 616021230 | B23: HOSPITAL DE MELIPILLA | C23: G MANNESCHI | D23: SANTIAGO I | E23: MELIPILLA | F23: REGIÓN DE METROPOLITANA DE SANTIAGO | G23: CN61602123 | H23: 61602123 | I23: PUBLICO | J23: GIANCARLO MANNESCHI GALLARDO
A24: 616022113 | B24: HOSPITAL DE CURANILAHUE | C24: R ARAYA | D24: SUR I | E24: CURANILAHUE | F24: REGIÓN DE BIOBÍO | G24: CN61602211 | H24: 61602211 | I24: PUBLICO | J24: RICARDO ENRIQUE ARAYA GONZÁLEZ
A25: 616066021 | B25: HOSPITAL DR. GUSTAVO FRICKE | C25: C VALENZUELA | D25: NORTE I | E25: VIÑA DEL MAR | F25: REGIÓN DE VALPARAÍSO | G25: CN61606602 | H25: 61606602 | I25: PUBLICO | J25: CONSTANZA VALENZUELA
A26: 616064029 | B26: HOSPITAL LA SERENA | C26: C VALENZUELA | D26: NORTE I | E26: LA SERENA | F26: REGIÓN DE COQUIMBO | G26: CN61606402 | H26: 61606402 | I26: PUBLICO | J26: CONSTANZA VALENZUELA
A27: 616022326 | B27: HOSPITAL DOCTOR HERNAN HENRIQUEZ ARAVENA | C27: M RUIZ | D27: SUR II | E27: TEMUCO | F27: REGIÓN DE LA ARAUCANÍA | G27: CN61602232 | H27: 61602232 | I27: PUBLICO | J27: MARCELO RUIZ
A28: 609100001 | B28: UNIVERSIDAD DE CHILE | C28: M RAMOS | D28: SANTIAGO II | E28: INDEPENDENCIA | F28: REGIÓN DE METROPOLITANA DE SANTIAGO | G28: CN60910000 | H28: 60910000 | I28: PUBLICO | J28: MAURICIO RAMOS MORENO
A29: 650754859 | B29: HOSPITAL CLINICO METROPOLITANA LA FLORIDA DRA ELOISA DIAZ INSUNZA | C29: M RAMOS | D29: SANTIAGO II | E29: LA FLORIDA | F29: REGIÓN DE METROPOLITANA DE SANTIAGO | G29: CN65075485 | H29: 65075485 | I29: PUBLICO | J29: MAURICIO RAMOS MORENO
A30: 616069179 | B30: HOSPITAL LINARES | C30: SUR III | D30: SUR III | E30: LINARES | F30: REGIÓN DE MAULE | G30: CN61606917 | H30: 61606917 | I30: PUBLICO | J30: ATENCION TELEFONICA
A31: 616070010 | B31: HOSPITAL CLINICO HERMINDA MARTIN | C31: R ARAYA | D31: SUR I | E31: CHILLÁN | F31: REGIÓN DE ÑUBLE | G31: CN61607001 | H31: 61607001 | I31: PUBLICO | J31: RICARDO ENRIQUE ARAYA GONZÁLEZ
A32: 907530000 | B32: CLINICA SANTA MARIA SPA | C32: M MARINAO | D32: SANTIAGO III | E32: PROVIDENCIA | F32: REGIÓN DE METROPOLITANA DE SANTIAGO | G32: CN90753000 | H32: 90753000 | I32: PRIVADO | J32: ATENCION TELEFONICA
A33: 61608402K | B33: INSTITUTO NACIONAL DEL TORAX | C33: M MARINAO | D33: SANTIAGO III | E33: PROVIDENCIA | F33: REGIÓN DE METROPOLITANA DE SANTIAGO | G33: CN61608402 | H33: 61608402 | I33: PUBLICO | J33: ATENCION TELEFONICA
A34: 710142009 | B34: CORMUN RANCAGUA - ADMINISTRACIÓN CENTRA | C34: SUR III | D34: SUR III | E34: RANCAGUA | F34: REGIÓN DE LIBERTADOR GENERAL BERNARDO O'HIGGINS | G34: CN71014200 | H34: 71014200 | I34: PUBLICO | J34: ATENCION TELEFONICA
A35: 616086057 | B35: DIRECCION ATENCION PRIMARIA, SERVICIO DE SALUD METROPOLITANO CENTRAL | C35: M MARINAO | D35: SANTIAGO III | E35: SANTIAGO | F35: REGIÓN DE METROPOLITANA DE SANTIAGO | G35: CN61608605 | H35: 61608605 | I35: PUBLICO | J35: ATENCION TELEFONICA
A36: 611020171 | B36: HOSPITAL NAVAL ALMIRANTE NEF | C36: C VALENZUELA | D36: NORTE I | E36: VIÑA DEL MAR | F36: REGIÓN DE VALPARAÍSO | G36: CN61102017 | H36: 61102017 | I36: PUBLICO | J36: CONSTANZA VALENZUELA
A37: 616021389 | B37: HOSPITAL REGIONAL RANCAGUA | C37: SUR III | D37: SUR III | E37: RANCAGUA | F37: REGIÓN DE LIBERTADOR GENERAL BERNARDO O'HIGGINS | G37: CN61602138 | H37: 61602138 | I37: PUBLICO | J37: ATENCION TELEFONICA
A38: 620008303 | B38: HOSPITAL COMPLEJO ASISTENCIAL PADRE LAS CASAS | C38: M RUIZ | D38: SUR II | E38: PADRE LAS CASAS | F38: REGIÓN DE LA ARAUCANÍA | G38: CN62000830 | H38: 62000830 | I38: PUBLICO | J38: MARCELO RUIZ
A39: 616062018 | B39: HOSPITAL REGIONAL DE ANTOFAGASTA | C39: M MARINAO | D39: SANTIAGO III | E39: ANTOFAGASTA | F39: REGIÓN DE ANTOFAGASTA | G39: CN61606201 | H39: 61606201 | I39: PUBLICO | J39: ATENCION TELEFONICA
A40: 691508005 | B40: I MUNICIPALIDAD DE TALCAHUANO | C40: R ARAYA | D40: SUR I | E40: TALCAHUANO | F40: REGIÓN DE BIOBÍO | G40: CN69150800 | H40: 69150800 | I40: PUBLICO | J40: RICARDO ENRIQUE ARAYA GONZÁLEZ
A41: 765150701 | B41: CLINICA ANDES SALUD CHILLAN S.A | C41: R ARAYA | D41: SUR I | E41: CHILLÁN | F41: REGIÓN DE ÑUBLE | G41: CN76515070 | H41: 76515070 | I41: PRIVADO | J41: RICARDO ENRIQUE ARAYA GONZÁLEZ
A42: 619585003 | B42: HOSPITAL PADRE ALBERTO HURTADO | C42: G MANNESCHI | D42: SANTIAGO I | E42: SAN RAMÓN | F42: REGIÓN DE METROPOLITANA DE SANTIAGO | G42: CN61958500 | H42: 61958500 | I42: PUBLICO | J42: GIANCARLO MANNESCHI GALLARDO
A43: 691809005 | B43: ILUSTRE MUNICIPALIDAD DE VICTORIA | C43: M RUIZ | D43: SUR II | E43: VICTORIA | F43: REGIÓN DE LA ARAUCANÍA | G43: CN69180900 | H43: 69180900 | I43: PUBLICO | J43: MARCELO RUIZ
...

Sheet CARTERA 2026
A1: RUT | B1: RAZON | C1: COMUNA | D1: REGION | E1: VENDEDOR | F1: COD CLIENTE | G1: INDUSTRIA | H1: SECTOR | I1: CARTERA | J1: REGION NOMBRE
A2: 35178651 | B2: FRANCISCO CAMPOS SANHUEZA | D2: 13 | E2: ATENCION TELEFONICA | F2: CN3517865 | I2: =IF(CARTERA_2026[[#This Row],[RUT]]=774097899,"DIST",_xlfn.XLOOKUP(CARTERA_2026[[#This Row],[VENDEDOR]],dimensiones!$C$21:$C$28,dimensiones!$D$21:$D$28,"")) -> ATEL | J2: =_xlfn.XLOOKUP(CARTERA_2026[[#This Row],[REGION]],dimensiones!C:C,dimensiones!D:D,"") -> Región de Metropolitana de Santiago
A3: 37531235 | B3: ANA ABURDENE | D3: 16 | E3: ATENCION TELEFONICA | F3: CN3753123 | I3: =IF(CARTERA_2026[[#This Row],[RUT]]=774097899,"DIST",_xlfn.XLOOKUP(CARTERA_2026[[#This Row],[VENDEDOR]],dimensiones!$C$21:$C$28,dimensiones!$D$21:$D$28,"")) -> ATEL | J3: =_xlfn.XLOOKUP(CARTERA_2026[[#This Row],[REGION]],dimensiones!C:C,dimensiones!D:D,"") -> Región de Ñuble
A4: 45008673 | B4: CLAUDIO ALVAREZ URRA | C4: SANTIAGO | D4: 13 | E4: ATENCION TELEFONICA | F4: CN4500867 | H4: PRIVADO | I4: =IF(CARTERA_2026[[#This Row],[RUT]]=774097899,"DIST",_xlfn.XLOOKUP(CARTERA_2026[[#This Row],[VENDEDOR]],dimensiones!$C$21:$C$28,dimensiones!$D$21:$D$28,"")) -> ATEL | J4: =_xlfn.XLOOKUP(CARTERA_2026[[#This Row],[REGION]],dimensiones!C:C,dimensiones!D:D,"") -> Región de Metropolitana de Santiago
A5: 50772888 | B5: TERESA DE JESUS ANDRADE ZELADA | D5: 13 | E5: ATENCION TELEFONICA | F5: CN5077288 | I5: =IF(CARTERA_2026[[#This Row],[RUT]]=774097899,"DIST",_xlfn.XLOOKUP(CARTERA_2026[[#This Row],[VENDEDOR]],dimensiones!$C$21:$C$28,dimensiones!$D$21:$D$28,"")) -> ATEL | J5: =_xlfn.XLOOKUP(CARTERA_2026[[#This Row],[REGION]],dimensiones!C:C,dimensiones!D:D,"") -> Región de Metropolitana de Santiago
A6: 53208193 | B6: BELARMINO SEGUNDO DONOSO FUENTES | D6: 13 | E6: ATENCION TELEFONICA | F6: CN5320819 | I6: =IF(CARTERA_2026[[#This Row],[RUT]]=774097899,"DIST",_xlfn.XLOOKUP(CARTERA_2026[[#This Row],[VENDEDOR]],dimensiones!$C$21:$C$28,dimensiones!$D$21:$D$28,"")) -> ATEL | J6: =_xlfn.XLOOKUP(CARTERA_2026[[#This Row],[REGION]],dimensiones!C:C,dimensiones!D:D,"") -> Región de Metropolitana de Santiago
A7: 63890022 | B7: ELIAS CORDOVA RUIZ | D7: 4 | E7: ATENCION TELEFONICA | F7: CN6389002 | I7: =IF(CARTERA_2026[[#This Row],[RUT]]=774097899,"DIST",_xlfn.XLOOKUP(CARTERA_2026[[#This Row],[VENDEDOR]],dimensiones!$C$21:$C$28,dimensiones!$D$21:$D$28,"")) -> ATEL | J7: =_xlfn.XLOOKUP(CARTERA_2026[[#This Row],[REGION]],dimensiones!C:C,dimensiones!D:D,"") -> Región de Coquimbo
A8: 64127217 | B8: DOCTOR SERGIO MAYORGA CIOCCA | D8: 13 | E8: ATENCION TELEFONICA | F8: CN6412721 | I8: =IF(CARTERA_2026[[#This Row],[RUT]]=774097899,"DIST",_xlfn.XLOOKUP(CARTERA_2026[[#This Row],[VENDEDOR]],dimensiones!$C$21:$C$28,dimensiones!$D$21:$D$28,"")) -> ATEL | J8: =_xlfn.XLOOKUP(CARTERA_2026[[#This Row],[REGION]],dimensiones!C:C,dimensiones!D:D,"") -> Región de Metropolitana de Santiago
A9: 64903209 | B9: VICTOR MANUEL BORJE ARAYA | D9: 13 | E9: ATENCION TELEFONICA | F9: CN6490320 | I9: =IF(CARTERA_2026[[#This Row],[RUT]]=774097899,"DIST",_xlfn.XLOOKUP(CARTERA_2026[[#This Row],[VENDEDOR]],dimensiones!$C$21:$C$28,dimensiones!$D$21:$D$28,"")) -> ATEL | J9: =_xlfn.XLOOKUP(CARTERA_2026[[#This Row],[REGION]],dimensiones!C:C,dimensiones!D:D,"") -> Región de Metropolitana de Santiago
A10: 73031095 | B10: JUAN A. RAMIREZ CASTILLO | D10: 9 | E10: ATENCION TELEFONICA | F10: CN7303109 | I10: =IF(CARTERA_2026[[#This Row],[RUT]]=774097899,"DIST",_xlfn.XLOOKUP(CARTERA_2026[[#This Row],[VENDEDOR]],dimensiones!$C$21:$C$28,dimensiones!$D$21:$D$28,"")) -> ATEL | J10: =_xlfn.XLOOKUP(CARTERA_2026[[#This Row],[REGION]],dimensiones!C:C,dimensiones!D:D,"") -> Región de La Araucanía
A11: 79186929 | B11: MANUEL EDUARDO VIDAL BARRIA | D11: 8 | E11: ATENCION TELEFONICA | F11: CN7918692 | I11: =IF(CARTERA_2026[[#This Row],[RUT]]=774097899,"DIST",_xlfn.XLOOKUP(CARTERA_2026[[#This Row],[VENDEDOR]],dimensiones!$C$21:$C$28,dimensiones!$D$21:$D$28,"")) -> ATEL | J11: =_xlfn.XLOOKUP(CARTERA_2026[[#This Row],[REGION]],dimensiones!C:C,dimensiones!D:D,"") -> Región de Biobío
A12: 81818320 | B12: LEOCADIA GONZALEZ TORO | D12: 14 | E12: ATENCION TELEFONICA | F12: CN8181832 | I12: =IF(CARTERA_2026[[#This Row],[RUT]]=774097899,"DIST",_xlfn.XLOOKUP(CARTERA_2026[[#This Row],[VENDEDOR]],dimensiones!$C$21:$C$28,dimensiones!$D$21:$D$28,"")) -> ATEL | J12: =_xlfn.XLOOKUP(CARTERA_2026[[#This Row],[REGION]],dimensiones!C:C,dimensiones!D:D,"") -> Región de Los Ríos
A13: 81850291 | B13: ISABEL LEIVA FUENTEALBA | D13: 16 | E13: ATENCION TELEFONICA | F13: CN8185029 | I13: =IF(CARTERA_2026[[#This Row],[RUT]]=774097899,"DIST",_xlfn.XLOOKUP(CARTERA_2026[[#This Row],[VENDEDOR]],dimensiones!$C$21:$C$28,dimensiones!$D$21:$D$28,"")) -> ATEL | J13: =_xlfn.XLOOKUP(CARTERA_2026[[#This Row],[REGION]],dimensiones!C:C,dimensiones!D:D,"") -> Región de Ñuble
A14: 81853363 | B14: ARTURO GUTIERREZ RUBILAR | D14: 9 | E14: ATENCION TELEFONICA | F14: CN8185336 | I14: =IF(CARTERA_2026[[#This Row],[RUT]]=774097899,"DIST",_xlfn.XLOOKUP(CARTERA_2026[[#This Row],[VENDEDOR]],dimensiones!$C$21:$C$28,dimensiones!$D$21:$D$28,"")) -> ATEL | J14: =_xlfn.XLOOKUP(CARTERA_2026[[#This Row],[REGION]],dimensiones!C:C,dimensiones!D:D,"") -> Región de La Araucanía
A15: 88248228 | B15: ERIKA IVONNE CACERES PAVEZ | D15: 13 | E15: ATENCION TELEFONICA | F15: CN8824822 | I15: =IF(CARTERA_2026[[#This Row],[RUT]]=774097899,"DIST",_xlfn.XLOOKUP(CARTERA_2026[[#This Row],[VENDEDOR]],dimensiones!$C$21:$C$28,dimensiones!$D$21:$D$28,"")) -> ATEL | J15: =_xlfn.XLOOKUP(CARTERA_2026[[#This Row],[REGION]],dimensiones!C:C,dimensiones!D:D,"") -> Región de Metropolitana de Santiago
A16: 91511959 | B16: FRANCISCO JAVIER PARDO QUIROZ | D16: 13 | E16: ATENCION TELEFONICA | F16: CN9151195 | I16: =IF(CARTERA_2026[[#This Row],[RUT]]=774097899,"DIST",_xlfn.XLOOKUP(CARTERA_2026[[#This Row],[VENDEDOR]],dimensiones!$C$21:$C$28,dimensiones!$D$21:$D$28,"")) -> ATEL | J16: =_xlfn.XLOOKUP(CARTERA_2026[[#This Row],[REGION]],dimensiones!C:C,dimensiones!D:D,"") -> Región de Metropolitana de Santiago
... A19: 106711038 | B19: ROSA BURGOS DOMINGUEZ | D19: 3 | E19: ATENCION TELEFONICA | F19: CN10671103 | I19: =IF(CARTERA_2026[[#This Row],[RUT]]=774097899,"DIST",_xlfn.XLOOKUP(CARTERA_2026[[#This Row],[VENDEDOR]],dimensiones!$C$21:$C$28,dimensiones!$D$21:$D$28,"")) -> ATEL | J19: =_xlfn.XLOOKUP(CARTERA_2026[[#This Row],[REGION]],dimensiones!C:C,dimensiones!D:D,"") -> Región de Atacama
A20: 118464397 | B20: CARLOS IGNACIO ARANCIBIA BARRENECHEA | C20: SANTIAGO | D20: 13 | E20: ATENCION TELEFONICA | F20: CN11846439 | H20: PRIVADO | I20: =IF(CARTERA_2026[[#This Row],[RUT]]=774097899,"DIST",_xlfn.XLOOKUP(CARTERA_2026[[#This Row],[VENDEDOR]],dimensiones!$C$21:$C$28,dimensiones!$D$21:$D$28,"")) -> ATEL | J20: =_xlfn.XLOOKUP(CARTERA_2026[[#This Row],[REGION]],dimensiones!C:C,dimensiones!D:D,"") -> Región de Metropolitana de Santiago
A21: 118726197 | B21: PAULA ANDREA RIVERA BRUNET | D21: 8 | E21: ATENCION TELEFONICA | F21: CN11872619 | I21: =IF(CARTERA_2026[[#This Row],[RUT]]=774097899,"DIST",_xlfn.XLOOKUP(CARTERA_2026[[#This Row],[VENDEDOR]],dimensiones!$C$21:$C$28,dimensiones!$D$21:$D$28,"")) -> ATEL | J21: =_xlfn.XLOOKUP(CARTERA_2026[[#This Row],[REGION]],dimensiones!C:C,dimensiones!D:D,"") -> Región de Biobío
A22: 121317834 | B22: HECTOR CARRENO BAEZA | D22: 13 | E22: ATENCION TELEFONICA | F22: CN12131783 | I22: =IF(CARTERA_2026[[#This Row],[RUT]]=774097899,"DIST",_xlfn.XLOOKUP(CARTERA_2026[[#This Row],[VENDEDOR]],dimensiones!$C$21:$C$28,dimensiones!$D$21:$D$28,"")) -> ATEL | J22: =_xlfn.XLOOKUP(CARTERA_2026[[#This Row],[REGION]],dimensiones!C:C,dimensiones!D:D,"") -> Región de Metropolitana de Santiago
A23: 122836576 | B23: MARGARITA RAILEN | D23: 13 | E23: ATENCION TELEFONICA | F23: CN12283657 | I23: =IF(CARTERA_2026[[#This Row],[RUT]]=774097899,"DIST",_xlfn.XLOOKUP(CARTERA_2026[[#This Row],[VENDEDOR]],dimensiones!$C$21:$C$28,dimensiones!$D$21:$D$28,"")) -> ATEL | J23: =_xlfn.XLOOKUP(CARTERA_2026[[#This Row],[REGION]],dimensiones!C:C,dimensiones!D:D,"") -> Región de Metropolitana de Santiago
A24: 150855403 | B24: ANDRES REYES | D24: 5 | E24: ATENCION TELEFONICA | F24: CN15085540 | I24: =IF(CARTERA_2026[[#This Row],[RUT]]=774097899,"DIST",_xlfn.XLOOKUP(CARTERA_2026[[#This Row],[VENDEDOR]],dimensiones!$C$21:$C$28,dimensiones!$D$21:$D$28,"")) -> ATEL | J24: =_xlfn.XLOOKUP(CARTERA_2026[[#This Row],[REGION]],dimensiones!C:C,dimensiones!D:D,"") -> Región de Valparaíso
A25: 161447579 | B25: IVAN CARLOS CANDIA ALDAY | D25: 13 | E25: ATENCION TELEFONICA | F25: CN16144757 | I25: =IF(CARTERA_2026[[#This Row],[RUT]]=774097899,"DIST",_xlfn.XLOOKUP(CARTERA_2026[[#This Row],[VENDEDOR]],dimensiones!$C$21:$C$28,dimensiones!$D$21:$D$28,"")) -> ATEL | J25: =_xlfn.XLOOKUP(CARTERA_2026[[#This Row],[REGION]],dimensiones!C:C,dimensiones!D:D,"") -> Región de Metropolitana de Santiago
A26: 165289676 | B26: MARCO ANTONIO ALBORNOZ SOTO | D26: 6 | E26: ATENCION TELEFONICA | F26: CN16528967 | I26: =IF(CARTERA_2026[[#This Row],[RUT]]=774097899,"DIST",_xlfn.XLOOKUP(CARTERA_2026[[#This Row],[VENDEDOR]],dimensiones!$C$21:$C$28,dimensiones!$D$21:$D$28,"")) -> ATEL | J26: =_xlfn.XLOOKUP(CARTERA_2026[[#This Row],[REGION]],dimensiones!C:C,dimensiones!D:D,"") -> Región de Libertador General Bernardo O'Higgins
A27: 173054734 | B27: ANDREA LUPAYANTE LUPAYÀNTE | D27: 13 | E27: ATENCION TELEFONICA | F27: CN17305473 | I27: =IF(CARTERA_2026[[#This Row],[RUT]]=774097899,"DIST",_xlfn.XLOOKUP(CARTERA_2026[[#This Row],[VENDEDOR]],dimensiones!$C$21:$C$28,dimensiones!$D$21:$D$28,"")) -> ATEL | J27: =_xlfn.XLOOKUP(CARTERA_2026[[#This Row],[REGION]],dimensiones!C:C,dimensiones!D:D,"") -> Región de Metropolitana de Santiago
A28: 176056827 | B28: JUAN ANDRES DIAZ GOMEZ | D28: 8 | E28: ATENCION TELEFONICA | F28: CN17605682 | I28: =IF(CARTERA_2026[[#This Row],[RUT]]=774097899,"DIST",_xlfn.XLOOKUP(CARTERA_2026[[#This Row],[VENDEDOR]],dimensiones!$C$21:$C$28,dimensiones!$D$21:$D$28,"")) -> ATEL | J28: =_xlfn.XLOOKUP(CARTERA_2026[[#This Row],[REGION]],dimensiones!C:C,dimensiones!D:D,"") -> Región de Biobío
A29: 176445467 | B29: HUMBERTO MIERES MORALES | D29: 13 | E29: ATENCION TELEFONICA | F29: CN17644546 | I29: =IF(CARTERA_2026[[#This Row],[RUT]]=774097899,"DIST",_xlfn.XLOOKUP(CARTERA_2026[[#This Row],[VENDEDOR]],dimensiones!$C$21:$C$28,dimensiones!$D$21:$D$28,"")) -> ATEL | J29: =_xlfn.XLOOKUP(CARTERA_2026[[#This Row],[REGION]],dimensiones!C:C,dimensiones!D:D,"") -> Región de Metropolitana de Santiago
A30: 180567933 | B30: LEONARDO QUEZADA VERGARA | D30: 13 | E30: ATENCION TELEFONICA | F30: CN18056793 | I30: =IF(CARTERA_2026[[#This Row],[RUT]]=774097899,"DIST",_xlfn.XLOOKUP(CARTERA_2026[[#This Row],[VENDEDOR]],dimensiones!$C$21:$C$28,dimensiones!$D$21:$D$28,"")) -> ATEL | J30: =_xlfn.XLOOKUP(CARTERA_2026[[#This Row],[REGION]],dimensiones!C:C,dimensiones!D:D,"") -> Región de Metropolitana de Santiago
A31: 188563619 | B31: JAVIER EDUARDO FLORES GOMEZ | D31: 3 | E31: ATENCION TELEFONICA | F31: CN18856361 | I31: =IF(CARTERA_2026[[#This Row],[RUT]]=774097899,"DIST",_xlfn.XLOOKUP(CARTERA_2026[[#This Row],[VENDEDOR]],dimensiones!$C$21:$C$28,dimensiones!$D$21:$D$28,"")) -> ATEL | J31: =_xlfn.XLOOKUP(CARTERA_2026[[#This Row],[REGION]],dimensiones!C:C,dimensiones!D:D,"") -> Región de Atacama
A32: 236451461 | B32: ANA MARIA TICONA APANA | D32: 13 | E32: ATENCION TELEFONICA | F32: CN23645146 | I32: =IF(CARTERA_2026[[#This Row],[RUT]]=774097899,"DIST",_xlfn.XLOOKUP(CARTERA_2026[[#This Row],[VENDEDOR]],dimensiones!$C$21:$C$28,dimensiones!$D$21:$D$28,"")) -> ATEL | J32: =_xlfn.XLOOKUP(CARTERA_2026[[#This Row],[REGION]],dimensiones!C:C,dimensiones!D:D,"") -> Región de Metropolitana de Santiago
... A35: 601030004 | B35: SUBSECRETARIA DE SERVICIOS SOCIALES | D35: 13 | E35: ATENCION TELEFONICA | F35: CN60103000 | I35: =IF(CARTERA_2026[[#This Row],[RUT]]=774097899,"DIST",_xlfn.XLOOKUP(CARTERA_2026[[#This Row],[VENDEDOR]],dimensiones!$C$21:$C$28,dimensiones!$D$21:$D$28,"")) -> ATEL | J35: =_xlfn.XLOOKUP(CARTERA_2026[[#This Row],[REGION]],dimensiones!C:C,dimensiones!D:D,"") -> Región de Metropolitana de Santiago
A36: 602020002 | B36: CAMARA DE DIPUTADOS DE CHILE | C36: VALPARAÍSO | D36: 5 | E36: ATENCION TELEFONICA | F36: CN60202000 | H36: PÚBLICO | I36: =IF(CARTERA_2026[[#This Row],[RUT]]=774097899,"DIST",_xlfn.XLOOKUP(CARTERA_2026[[#This Row],[VENDEDOR]],dimensiones!$C$21:$C$28,dimensiones!$D$21:$D$28,"")) -> ATEL | J36: =_xlfn.XLOOKUP(CARTERA_2026[[#This Row],[REGION]],dimensiones!C:C,dimensiones!D:D,"") -> Región de Valparaíso
A37: 605060005 | B37: POLICIA DE INVESTIGACIONES DE CHILE | D37: 10 | E37: ATENCION TELEFONICA | F37: CN60506000 | I37: =IF(CARTERA_2026[[#This Row],[RUT]]=774097899,"DIST",_xlfn.XLOOKUP(CARTERA_2026[[#This Row],[VENDEDOR]],dimensiones!$C$21:$C$28,dimensiones!$D$21:$D$28,"")) -> ATEL | J37: =_xlfn.XLOOKUP(CARTERA_2026[[#This Row],[REGION]],dimensiones!C:C,dimensiones!D:D,"") -> Región de Los Lagos
A38: 605060129 | B38: ESCUELA DE INVESTIGACIONES POLICIALES (ESCIPOL) | D38: 13 | E38: ATENCION TELEFONICA | F38: CN60506012 | I38: =IF(CARTERA_2026[[#This Row],[RUT]]=774097899,"DIST",_xlfn.XLOOKUP(CARTERA_2026[[#This Row],[VENDEDOR]],dimensiones!$C$21:$C$28,dimensiones!$D$21:$D$28,"")) -> ATEL | J38: =_xlfn.XLOOKUP(CARTERA_2026[[#This Row],[REGION]],dimensiones!C:C,dimensiones!D:D,"") -> Región de Metropolitana de Santiago
A39: 605111300 | B39: INTENDENCIA REGION METROPOLITANA | D39: 13 | E39: ATENCION TELEFONICA | F39: CN60511130 | I39: =IF(CARTERA_2026[[#This Row],[RUT]]=774097899,"DIST",_xlfn.XLOOKUP(CARTERA_2026[[#This Row],[VENDEDOR]],dimensiones!$C$21:$C$28,dimensiones!$D$21:$D$28,"")) -> ATEL | J39: =_xlfn.XLOOKUP(CARTERA_2026[[#This Row],[REGION]],dimensiones!C:C,dimensiones!D:D,"") -> Región de Metropolitana de Santiago
A40: 609020636 | B40: ILUSTRE MUNICIPALIDAD DE LINARES | D40: 7 | E40: ATENCION TELEFONICA | F40: CN60902063 | I40: =IF(CARTERA_2026[[#This Row],[RUT]]=774097899,"DIST",_xlfn.XLOOKUP(CARTERA_2026[[#This Row],[VENDEDOR]],dimensiones!$C$21:$C$28,dimensiones!$D$21:$D$28,"")) -> ATEL | J40: =_xlfn.XLOOKUP(CARTERA_2026[[#This Row],[REGION]],dimensiones!C:C,dimensiones!D:D,"") -> Región de Maule
A41: 609050004 | B41: SERVICIO NACIONAL DEL PATRIMONIO CULTURAL | D41: 4 | E41: ATENCION TELEFONICA | F41: CN60905000 | I41: =IF(CARTERA_2026[[#This Row],[RUT]]=774097899,"DIST",_xlfn.XLOOKUP(CARTERA_2026[[#This Row],[VENDEDOR]],dimensiones!$C$21:$C$28,dimensiones!$D$21:$D$28,"")) -> ATEL | J41: =_xlfn.XLOOKUP(CARTERA_2026[[#This Row],[REGION]],dimensiones!C:C,dimensiones!D:D,"") -> Región de Coquimbo
A42: 609100478 | B42: UNIVERSIDAD METROPOLITANA DE CIENCIAS DE LA EDUCACION | D42: 13 | E42: ATENCION TELEFONICA | F42: CN60910047 | I42: =IF(CARTERA_2026[[#This Row],[RUT]]=774097899,"DIST",_xlfn.XLOOKUP(CARTERA_2026[[#This Row],[VENDEDOR]],dimensiones!$C$21:$C$28,dimensiones!$D$21:$D$28,"")) -> ATEL | J42: =_xlfn.XLOOKUP(CARTERA_2026[[#This Row],[REGION]],dimensiones!C:C,dimensiones!D:D,"") -> Región de Metropolitana de Santiago
A43: 609110066 | B43: UNIVERSIDAD DEL BIO BIO | D43: 8 | E43: ATENCION TELEFONICA | F43: CN60911006 | I43: =IF(CARTERA_2026[[#This Row],[RUT]]=774097899,"DIST",_xlfn.XLOOKUP(CARTERA_2026[[#This Row],[VENDEDOR]],dimensiones!$C$21:$C$28,dimensiones!$D$21:$D$28,"")) -> ATEL | J43: =_xlfn.XLOOKUP(CARTERA_2026[[#This Row],[REGION]],dimensiones!C:C,dimensiones!D:D,"") -> Región de Biobío
A44: 610040071 | B44: DIRECCION REGIONAL DE GENDARMERIA - ANTOFAGASTA | D44: 2 | E44: ATENCION TELEFONICA | F44: CN61004007 | I44: =IF(CARTERA_2026[[#This Row],[RUT]]=774097899,"DIST",_xlfn.XLOOKUP(CARTERA_2026[[#This Row],[VENDEDOR]],dimensiones!$C$21:$C$28,dimensiones!$D$21:$D$28,"")) -> ATEL | J44: =_xlfn.XLOOKUP(CARTERA_2026[[#This Row],[REGION]],dimensiones!C:C,dimensiones!D:D,"") -> Región de Antofagasta
...

Sheet cnb
C1: Rut Facturador | D1: k | G1: Código SN | H1: Nombre SN | I1: Número de identificación fiscal | L1: 61602040-4
C2: 61602212-1 | D2: =_xlfn.XLOOKUP(C2,I:I,G:G,"") -> CN61602212 | G2: CN69110400 | H2: I MUNICIPALIDAD DE TALCA | I2: 69110400-1
C3: 61602236-9 | D3: =_xlfn.XLOOKUP(C3,I:I,G:G,"") -> CN61602236 | G3: CN69051000 | H3: I MUNICIPALIDAD DE SANTA MARIA | I3: 69051000-6
C4: 61606404-5 | D4: =_xlfn.XLOOKUP(C4,I:I,G:G,"") -> CN61606404 | G4: CN69254900 | H4: I. MUNICIPALIDAD PEDRO AGUIRRE CERDA | I4: 69254900-7
C5: 61606913-6 | D5: =_xlfn.XLOOKUP(C5,I:I,G:G,"") -> CN61606913 | G5: CN69100200 | H5: MUNICIPALIDAD ROMERAL | I5: 69100200-4
C6: 62000830-3 | D6: =_xlfn.XLOOKUP(C6,I:I,G:G,"") -> CN62000830 | G6: CN61602312 | H6: HOSPITAL ALTO PALENA | I6: 61602312-8
C7: 69010100-9 | D7: =_xlfn.XLOOKUP(C7,I:I,G:G,"") -> CN69010100 | G7: CN69220800 | H7: ILUSTRE MUNICIPALIDAD DE LOS MUERMOS | I7: 69220800-5
C8: 69141300-4 | D8: =_xlfn.XLOOKUP(C8,I:I,G:G,"") -> CN69141300 | G8: CN69170402 | H8: I. MUNICIPALIDAD QUILLECO | I8: 69170402-5
C9: 69141300-4 | D9: =_xlfn.XLOOKUP(C9,I:I,G:G,"") -> CN69141300 | G9: CN69110700 | H9: ILUSTRE MUNICIPALIDAD DE RIO CLARO | I9: 69110700-0
C10: 69150502-2 | D10: =_xlfn.XLOOKUP(C10,I:I,G:G,"") -> CN69150502 | G10: CN61602224 | H10: HOSPITAL PUREN | I10: 61602224-5
C11: 69254800-0 | D11: =_xlfn.XLOOKUP(C11,I:I,G:G,"") -> CN69254800 | G11: PN97023000 | H11: BANCO ITAU CHILE | I11: 97023000-9
C12: 69255300-4 | D12: =_xlfn.XLOOKUP(C12,I:I,G:G,"") -> CN69255300 | G12: CN69050800 | H12: I MUNICIPALIDAD DE PANQUEHUE | I12: 69050800-1
C13: 69261400-3 | D13: =_xlfn.XLOOKUP(C13,I:I,G:G,"") -> CN69261400 | G13: CN53335808 | H13: CONS EXTERNO VALDIVIA | I13: 53335808-K
... C83: 62000830-3 | D83: =_xlfn.XLOOKUP(C83,I:I,G:G,"") -> CN62000830 | G83: CN61606402 | H83: HOSPITAL LA SERENA | I83: 61606402-9
G84: CN69260400 | H84: MUNIC QUILLOTA DPTO SALUD | I84: 69260400-8
G85: CN70983600 | H85: CORP.MUNICIPAL PARA DES.SOCIAL-V.ALEMANA | I85: 70983600-5
G86: CN61606905 | H86: HOSPITAL LICANTEN | I86: 61606905-5
G87: CN61602248 | H87: HOSPITAL VILLARRICA | I87: 61602248-2
G88: CN69191200 | H88: ILUSTRE MUNICIPALIDAD DE GORBEA | I88: 69191200-0
G89: CN61606911 | H89: HOSPITAL DE CONSTITUCION | I89: 61606911-K
G90: CN69200300 | H90: MUNIC LANCO | I90: 69200300-4
G91: CN69060200 | H91: I MUNICIPALIDAD DE LA CRUZ | I91: 69060200-8
G92: CN61606915 | H92: HOSPITAL CHANCO | I92: 61606915-2
G93: CN65311270 | H93: CENTRO CLINICO MILITAR CONCEPCION | I93: 65311270-K
G94: CN77223544 | H94: COMERCIALIZADORA Y DISTRIBUIDORA VASSAN LTDA | I94: 77223544-5
G95: BH4524354 | H95: GERMAN DEL FIERRO MERY | I95: 4524354-0
... G335: CN61602262 | H335: HOSPITAL RIO NEGRO | I335: 61602262-8
G336: EM154270272 | H336: MARCELO ALEXIS RUIZ RUIZ | I336: 154270272
G337: CN69151100 | H337: MUNICIPALIDAD SAN ROSENDO | I337: 69151100-6
G338: CN61606907 | H338: HOSPITAL TENO | I338: 61606907-1
G339: CN69151400 | H339: MUNICIPALIDAD SANTA JUANA | I339: 69151400-5
G340: CN69190700 | H340: MUNICIPALIDAD DE TEMUCO | I340: 69190700-7
G341: CN70933700 | H341: CORP MUNICIPAL DE EDUC SALUD CULTURA Y RECREACION DE LA FLORIDA | I341: 70933700-9
G342: CN69151202 | H342: I MUNICIPALIDAD DE CORONEL DPTO ADMINIST | I342: 69151202-9
G343: CN61607508 | H343: HOSPITAL RIO BUENO | I343: 61607508-K
G344: CN61602198 | H344: HOSPITAL DE PENCO | I344: 61602198-2
G345: EM25343424 | H345: YELISMAR ARLEIDY CHACON | I345: 25343424-4
G346: CN69080400 | H346: ILUSTRE MUNICIPALIDAD DE CODEGUA | I346: 69080400-K
G347: CN69030300 | H347: I MUNICIPALIDAD DE CALDERA | I347: 69030300-0
G348: CN69170300 | H348: MUNICIPALIDAD LAJA | I348: 69170300-2
...

Sheet dimensiones
C2: Region | D2: Nombre Región | I2: RUT
C3: 1 | D3: Región de Tarapacá | I3: 616084038
C4: 2 | D4: Región de Antofagasta | I4: 616084070
C5: 3 | D5: Región de Atacama | I5: 616084089
C6: 4 | D6: Región de Coquimbo | I6: 619794508
C7: 5 | D7: Región de Valparaíso | I7: 703774008
C8: 6 | D8: Región de Libertador General Bernardo O'Higgins | I8: 780405201
C9: 7 | D9: Región de Maule | I9: 907530000
